Workbook
Name Slicer_Charge_Category: #N/A
Name Slicer_Contract: #N/A
Name Slicer_MultipleLines: #N/A

Sheet Overview
A1: TELCO CUSTOMER WORKBOOK
A2: Statistical overview, analysis, and supporting customer data
A6: CONTENTS
A7: Statistical Insights | B7: Key findings, live KPI references, comparison tables, and charts.
A8: Customer Records | B8: Complete 7,043-row telco customer dataset across 21 fields.
A9: Descriptive Stats | B9: Descriptive statistics for senior status, tenure, monthly charges, and total charges.
A10: Numeric Extract | B10: Four numeric fields extracted for supporting analysis.

Sheet Statistical Insights
A1: DESCRIPTIVE STATISTICS INSIGHTS
A2: Initial read of the selected worksheet • 7,043 customer records
A4: CUSTOMERS | C4: SENIOR SHARE | E4: AVG TENURE | G4: MISSING TOTAL CHARGES
A5: ='Descriptive Stats'!B15 -> 7043 | C5: ='Descriptive Stats'!B3 -> 0.16214681 | E5: ='Descriptive Stats'!D3 -> 32.371149 | G5: ='Descriptive Stats'!B15-'Descriptive Stats'!H15 -> 11
A8: KEY FINDINGS
A9: 1. The customer base is mostly non-senior: seniors represent 16.2% (1,142 of 7,043 customers).
A10: 2. Tenure is widely dispersed: the average is 32.4 months, but the most common tenure is only 1 month, signaling a sizable new-customer segment.
A11: 3. Total charges are strongly right-skewed (0.96): the $2,283 average is 63% above the $1,397 median, so the median better describes a typical customer.
A12: 4. Total charges contain 11 missing records; address these before customer-level modeling or churn-driver analysis.
A14: METRIC PROFILE
A15: Metric | B15: Mean | C15: Median | D15: Std Dev | E15: Range | F15: Initial interpretation
A16: SeniorCitizen | B16: ='Descriptive Stats'!B3 -> 0.16214681 | C16: ='Descriptive Stats'!B5 -> 0 | D16: ='Descriptive Stats'!B7 -> 0.36861161 | E16: ='Descriptive Stats'!B11 -> 1 | F16: ="Binary share; "&TEXT(B16,"0.0%")&" of customers are seniors." -> Binary share; 16.2% of customers are seniors.
A17: Tenure (months) | B17: ='Descriptive Stats'!D3 -> 32.371149 | C17: ='Descriptive Stats'!D5 -> 29 | D17: ='Descriptive Stats'!D7 -> 24.559481 | E17: ='Descriptive Stats'!D11 -> 72 | F17: ="Broad spread across 0–72 months; mode is 1 month." -> Broad spread across 0–72 months; mode is 1 month.
A18: Monthly charges | B18: ='Descriptive Stats'!F3 -> 64.761692 | C18: ='Descriptive Stats'!F5 -> 70.35 | D18: ='Descriptive Stats'!F7 -> 30.090047 | E18: ='Descriptive Stats'!F11 -> 100.5 | F18: ="Median exceeds mean; distribution is slightly left-skewed." -> Median exceeds mean; distribution is slightly left-skewed.
A19: Total charges | B19: ='Descriptive Stats'!H3 -> 2283.3004 | C19: ='Descriptive Stats'!H5 -> 1397.475 | D19: ='Descriptive Stats'!H7 -> 2266.7714 | E19: ='Descriptive Stats'!H11 -> 8666 | F19: ="High variability and right skew; 11 observations are missing." -> High variability and right skew; 11 observations are missing.
A21: COMPARATIVE SIGNALS
A22: Metric | B22: Relative variability | C22: Median as % of mean
A23: Tenure | B23: =D17/B17 -> 0.75868426 | C23: =C17/B17 -> 0.89585947
A24: Monthly charges | B24: =D18/B18 -> 0.46462725 | C24: =C18/B18 -> 1.0862903
A25: Total charges | B25: =D19/B19 -> 0.99276088 | C25: =C19/B19 -> 0.61204166

Sheet Customer Records
A1: customerID | B1: gender | C1: SeniorCitizen | D1: Partner | E1: Dependents | F1: tenure | G1: PhoneService | H1: MultipleLines | I1: InternetService | J1: OnlineSecurity | K1: OnlineBackup | L1: DeviceProtection | M1: TechSupport | N1: StreamingTV | O1: StreamingMovies | P1: Contract | Q1: PaperlessBilling | R1: PaymentMethod | S1: MonthlyCharges | T1: Charge Category | U1: TotalCharges | V1: Churn
A2: 7590-Vhveg | B2: Female | C2: 0 | D2: Yes | E2: No | F2: 1 | G2: No | H2: No Phone Service | I2: Dsl | J2: No | K2: Yes | L2: No | M2: No | N2: No | O2: No | P2: Month-To-Month | Q2: Yes | R2: Electronic Check | S2: 29.85 | T2: =IF(Table1[[#This Row],[MonthlyCharges]]<=51,"Low",IF(Table1[[#This Row],[MonthlyCharges]]<=84,"Medium","High")) -> Low | U2: 29.85 | V2: No
A3: 5575-Gnvde | B3: Male | C3: 0 | D3: No | E3: No | F3: 34 | G3: Yes | H3: No | I3: Dsl | J3: Yes | K3: No | L3: Yes | M3: No | N3: No | O3: No | P3: One Year | Q3: No | R3: Mailed Check | S3: 56.95 | T3: =IF(Table1[[#This Row],[MonthlyCharges]]<=51,"Low",IF(Table1[[#This Row],[MonthlyCharges]]<=84,"Medium","High")) -> Medium | U3: 1889.5 | V3: No
A4: 3668-Qpybk | B4: Male | C4: 0 | D4: No | E4: No | F4: 2 | G4: Yes | H4: No | I4: Dsl | J4: Yes | K4: Yes | L4: No | M4: No | N4: No | O4: No | P4: Month-To-Month | Q4: Yes | R4: Mailed Check | S4: 53.85 | T4: =IF(Table1[[#This Row],[MonthlyCharges]]<=51,"Low",IF(Table1[[#This Row],[MonthlyCharges]]<=84,"Medium","High")) -> Medium | U4: 108.15 | V4: Yes
A5: 7795-Cfocw | B5: Male | C5: 0 | D5: No | E5: No | F5: 45 | G5: No | H5: No Phone Service | I5: Dsl | J5: Yes | K5: No | L5: Yes | M5: Yes | N5: No | O5: No | P5: One Year | Q5: No | R5: Bank Transfer (Automatic) | S5: 42.3 | T5: =IF(Table1[[#This Row],[MonthlyCharges]]<=51,"Low",IF(Table1[[#This Row],[MonthlyCharges]]<=84,"Medium","High")) -> Low | U5: 1840.75 | V5: No
A6: 9237-Hqitu | B6: Female | C6: 0 | D6: No | E6: No | F6: 2 | G6: Yes | H6: No | I6: Fiber Optic | J6: No | K6: No | L6: No | M6: No | N6: No | O6: No | P6: Month-To-Month | Q6: Yes | R6: Electronic Check | S6: 70.7 | T6: =IF(Table1[[#This Row],[MonthlyCharges]]<=51,"Low",IF(Table1[[#This Row],[MonthlyCharges]]<=84,"Medium","High")) -> Medium | U6: 151.65 | V6: Yes
A7: 9305-Cdskc | B7: Female | C7: 0 | D7: No | E7: No | F7: 8 | G7: Yes | H7: Yes | I7: Fiber Optic | J7: No | K7: No | L7: Yes | M7: No | N7: Yes | O7: Yes | P7: Month-To-Month | Q7: Yes | R7: Electronic Check | S7: 99.65 | T7: =IF(Table1[[#This Row],[MonthlyCharges]]<=51,"Low",IF(Table1[[#This Row],[MonthlyCharges]]<=84,"Medium","High")) -> High | U7: 820.5 | V7: Yes
A8: 1452-Kiovk | B8: Male | C8: 0 | D8: No | E8: Yes | F8: 22 | G8: Yes | H8: Yes | I8: Fiber Optic | J8: No | K8: Yes | L8: No | M8: No | N8: Yes | O8: No | P8: Month-To-Month | Q8: Yes | R8: Credit Card (Automatic) | S8: 89.1 | T8: =IF(Table1[[#This Row],[MonthlyCharges]]<=51,"Low",IF(Table1[[#This Row],[MonthlyCharges]]<=84,"Medium","High")) -> High | U8: 1949.4 | V8: No
A9: 6713-Okomc | B9: Female | C9: 0 | D9: No | E9: No | F9: 10 | G9: No | H9: No Phone Service | I9: Dsl | J9: Yes | K9: No | L9: No | M9: No | N9: No | O9: No | P9: Month-To-Month | Q9: No | R9: Mailed Check | S9: 29.75 | T9: =IF(Table1[[#This Row],[MonthlyCharges]]<=51,"Low",IF(Table1[[#This Row],[MonthlyCharges]]<=84,"Medium","High")) -> Low | U9: 301.9 | V9: No
A10: 7892-Pookp | B10: Female | C10: 0 | D10: Yes | E10: No | F10: 28 | G10: Yes | H10: Yes | I10: Fiber Optic | J10: No | K10: No | L10: Yes | M10: Yes | N10: Yes | O10: Yes | P10: Month-To-Month | Q10: Yes | R10: Electronic Check | S10: 104.8 | T10: =IF(Table1[[#This Row],[MonthlyCharges]]<=51,"Low",IF(Table1[[#This Row],[MonthlyCharges]]<=84,"Medium","High")) -> High | U10: 3046.05 | V10: Yes
A11: 6388-Tabgu | B11: Male | C11: 0 | D11: No | E11: Yes | F11: 62 | G11: Yes | H11: No | I11: Dsl | J11: Yes | K11: Yes | L11: No | M11: No | N11: No | O11: No | P11: One Year | Q11: No | R11: Bank Transfer (Automatic) | S11: 56.15 | T11: =IF(Table1[[#This Row],[MonthlyCharges]]<=51,"Low",IF(Table1[[#This Row],[MonthlyCharges]]<=84,"Medium","High")) -> Medium | U11: 3487.95 | V11: No
A12: 9763-Grskd | B12: Male | C12: 0 | D12: Yes | E12: Yes | F12: 13 | G12: Yes | H12: No | I12: Dsl | J12: Yes | K12: No | L12: No | M12: No | N12: No | O12: No | P12: Month-To-Month | Q12: Yes | R12: Mailed Check | S12: 49.95 | T12: =IF(Table1[[#This Row],[MonthlyCharges]]<=51,"Low",IF(Table1[[#This Row],[MonthlyCharges]]<=84,"Medium","High")) -> Low | U12: 587.45 | V12: No
A13: 7469-Lkbci | B13: Male | C13: 0 | D13: No | E13: No | F13: 16 | G13: Yes | H13: No | I13: No | J13: No Internet Service | K13: No Internet Service | L13: No Internet Service | M13: No Internet Service | N13: No Internet Service | O13: No Internet Service | P13: Two Year | Q13: No | R13: Credit Card (Automatic) | S13: 18.95 | T13: =IF(Table1[[#This Row],[MonthlyCharges]]<=51,"Low",IF(Table1[[#This Row],[MonthlyCharges]]<=84,"Medium","High")) -> Low | U13: 326.8 | V13: No
... A489: 3649-Jpugy | B489: Male | C489: 0 | D489: No | E489: No | F489: 72 | G489: Yes | H489: Yes | I489: Dsl | J489: No | K489: Yes | L489: Yes | M489: Yes | N489: Yes | O489: Yes | P489: Two Year | Q489: Yes | R489: Bank Transfer (Automatic) | S489: 88.6 | T489: =IF(Table1[[#This Row],[MonthlyCharges]]<=51,"Low",IF(Table1[[#This Row],[MonthlyCharges]]<=84,"Medium","High")) -> High | U489: 6201.95 | V489: No
A490: 4472-Lvygi | B490: Female | C490: 0 | D490: Yes | E490: Yes | F490: 0 | G490: No | H490: No Phone Service | I490: Dsl | J490: Yes | K490: No | L490: Yes | M490: Yes | N490: Yes | O490: No | P490: Two Year | Q490: Yes | R490: Bank Transfer (Automatic) | S490: 52.55 | T490: =IF(Table1[[#This Row],[MonthlyCharges]]<=51,"Low",IF(Table1[[#This Row],[MonthlyCharges]]<=84,"Medium","High")) -> Medium | V490: No
A491: 8372-Juxui | B491: Male | C491: 0 | D491: No | E491: Yes | F491: 1 | G491: Yes | H491: Yes | I491: Fiber Optic | J491: No | K491: No | L491: No | M491: No | N491: No | O491: No | P491: Month-To-Month | Q491: Yes | R491: Electronic Check | S491: 74.35 | T491: =IF(Table1[[#This Row],[MonthlyCharges]]<=51,"Low",IF(Table1[[#This Row],[MonthlyCharges]]<=84,"Medium","High")) -> Medium | U491: 74.35 | V491: Yes
A492: 3552-Ctcyf | B492: Male | C492: 0 | D492: Yes | E492: Yes | F492: 63 | G492: Yes | H492: Yes | I492: Fiber Optic | J492: No | K492: Yes | L492: Yes | M492: No | N492: Yes | O492: Yes | P492: Two Year | Q492: Yes | R492: Bank Transfer (Automatic) | S492: 104.8 | T492: =IF(Table1[[#This Row],[MonthlyCharges]]<=51,"Low",IF(Table1[[#This Row],[MonthlyCharges]]<=84,"Medium","High")) -> High | U492: 6597.25 | V492: No
A493: 6778-Ysnih | B493: Female | C493: 0 | D493: No | E493: No | F493: 2 | G493: Yes | H493: No | I493: Dsl | J493: No | K493: Yes | L493: No | M493: No | N493: Yes | O493: No | P493: Month-To-Month | Q493: Yes | R493: Electronic Check | S493: 59 | T493: =IF(Table1[[#This Row],[MonthlyCharges]]<=51,"Low",IF(Table1[[#This Row],[MonthlyCharges]]<=84,"Medium","High")) -> Medium | U493: 114.15 | V493: No
A494: 0388-Eopex | B494: Female | C494: 0 | D494: Yes | E494: No | F494: 2 | G494: Yes | H494: No | I494: Fiber Optic | J494: Yes | K494: No | L494: No | M494: No | N494: No | O494: No | P494: Month-To-Month | Q494: Yes | R494: Electronic Check | S494: 74.4 | T494: =IF(Table1[[#This Row],[MonthlyCharges]]<=51,"Low",IF(Table1[[#This Row],[MonthlyCharges]]<=84,"Medium","High")) -> Medium | U494: 139.4 | V494: Yes
A495: 5756-Ozrio | B495: Male | C495: 1 | D495: Yes | E495: No | F495: 61 | G495: Yes | H495: Yes | I495: Dsl | J495: No | K495: Yes | L495: No | M495: No | N495: No | O495: Yes | P495: One Year | Q495: No | R495: Bank Transfer (Automatic) | S495: 64.05 | T495: =IF(Table1[[#This Row],[MonthlyCharges]]<=51,"Low",IF(Table1[[#This Row],[MonthlyCharges]]<=84,"Medium","High")) -> Medium | U495: 3902.6 | V495: No
A496: 6579-Jpicp | B496: Male | C496: 0 | D496: No | E496: No | F496: 1 | G496: Yes | H496: No | I496: No | J496: No Internet Service | K496: No Internet Service | L496: No Internet Service | M496: No Internet Service | N496: No Internet Service | O496: No Internet Service | P496: Month-To-Month | Q496: No | R496: Mailed Check | S496: 20.4 | T496: =IF(Table1[[#This Row],[MonthlyCharges]]<=51,"Low",IF(Table1[[#This Row],[MonthlyCharges]]<=84,"Medium","High")) -> Low | U496: 20.4 | V496: No
A497: 8205-Otchb | B497: Male | C497: 0 | D497: No | E497: No | F497: 22 | G497: No | H497: No Phone Service | I497: Dsl | J497: No | K497: Yes | L497: Yes | M497: No | N497: No | O497: Yes | P497: One Year | Q497: Yes | R497: Bank Transfer (Automatic) | S497: 43.75 | T497: =IF(Table1[[#This Row],[MonthlyCharges]]<=51,"Low",IF(Table1[[#This Row],[MonthlyCharges]]<=84,"Medium","High")) -> Low | U497: 903.6 | V497: Yes
A498: 4134-Bsxlx | B498: Male | C498: 0 | D498: Yes | E498: No | F498: 28 | G498: Yes | H498: No | I498: Dsl | J498: Yes | K498: Yes | L498: No | M498: Yes | N498: No | O498: No | P498: Month-To-Month | Q498: No | R498: Mailed Check | S498: 60.9 | T498: =IF(Table1[[#This Row],[MonthlyCharges]]<=51,"Low",IF(Table1[[#This Row],[MonthlyCharges]]<=84,"Medium","High")) -> Medium | U498: 1785.65 | V498: No
A499: 0505-Spoow | B499: Female | C499: 0 | D499: Yes | E499: No | F499: 70 | G499: Yes | H499: No | I499: No | J499: No Internet Service | K499: No Internet Service | L499: No Internet Service | M499: No Internet Service | N499: No Internet Service | O499: No Internet Service | P499: Two Year | Q499: No | R499: Bank Transfer (Automatic) | S499: 19.8 | T499: =IF(Table1[[#This Row],[MonthlyCharges]]<=51,"Low",IF(Table1[[#This Row],[MonthlyCharges]]<=84,"Medium","High")) -> Low | U499: 1397.65 | V499: No
A500: 6235-Vdhom | B500: Female | C500: 1 | D500: No | E500: No | F500: 5 | G500: No | H500: No Phone Service | I500: Dsl | J500: No | K500: Yes | L500: No | M500: No | N500: No | O500: No | P500: Month-To-Month | Q500: No | R500: Electronic Check | S500: 28.45 | T500: =IF(Table1[[#This Row],[MonthlyCharges]]<=51,"Low",IF(Table1[[#This Row],[MonthlyCharges]]<=84,"Medium","High")) -> Low | U500: 131.05 | V500: Yes
A501: 7783-Ykgdv | B501: Female | C501: 0 | D501: No | E501: No | F501: 12 | G501: Yes | H501: Yes | I501: Fiber Optic | J501: Yes | K501: Yes | L501: Yes | M501: No | N501: No | O501: Yes | P501: Month-To-Month | Q501: Yes | R501: Bank Transfer (Automatic) | S501: 99.7 | T501: =IF(Table1[[#This Row],[MonthlyCharges]]<=51,"Low",IF(Table1[[#This Row],[MonthlyCharges]]<=84,"Medium","High")) -> High | U501: 1238.45 | V501: Yes
A502: 4374-Ymusq | B502: Male | C502: 0 | D502: No | E502: No | F502: 34 | G502: Yes | H502: Yes | I502: Fiber Optic | J502: Yes | K502: Yes | L502: Yes | M502: Yes | N502: Yes | O502: Yes | P502: One Year | Q502: No | R502: Credit Card (Automatic) | S502: 116.25 | T502: =IF(Table1[[#This Row],[MonthlyCharges]]<=51,"Low",IF(Table1[[#This Row],[MonthlyCharges]]<=84,"Medium","High")) -> High | U502: 3899.05 | V502: No
... A754: 1410-Rscmr | B754: Male | C754: 0 | D754: Yes | E754: Yes | F754: 7 | G754: Yes | H754: No | I754: Dsl | J754: Yes | K754: No | L754: Yes | M754: Yes | N754: No | O754: Yes | P754: Month-To-Month | Q754: Yes | R754: Credit Card (Automatic) | S754: 71.35 | T754: =IF(Table1[[#This Row],[MonthlyCharges]]<=51,"Low",IF(Table1[[#This Row],[MonthlyCharges]]<=84,"Medium","High")) -> Medium | U754: 515.75 | V754: No
A755: 3115-Czmzd | B755: Male | C755: 0 | D755: No | E755: Yes | F755: 0 | G755: Yes | H755: No | I755: No | J755: No Internet Service | K755: No Internet Service | L755: No Internet Service | M755: No Internet Service | N755: No Internet Service | O755: No Internet Service | P755: Two Year | Q755: No | R755: Mailed Check | S755: 20.25 | T755: =IF(Table1[[#This Row],[MonthlyCharges]]<=51,"Low",IF(Table1[[#This Row],[MonthlyCharges]]<=84,"Medium","High")) -> Low | V755: No
A756: 0139-Ivfjg | B756: Female | C756: 0 | D756: Yes | E756: No | F756: 2 | G756: Yes | H756: No | I756: Fiber Optic | J756: Yes | K756: Yes | L756: No | M756: No | N756: Yes | O756: No | P756: Month-To-Month | Q756: No | R756: Electronic Check | S756: 90.35 | T756: =IF(Table1[[#This Row],[MonthlyCharges]]<=51,"Low",IF(Table1[[#This Row],[MonthlyCharges]]<=84,"Medium","High")) -> High | U756: 190.5 | V756: No
A757: 6683-Vlctz | B757: Male | C757: 1 | D757: No | E757: No | F757: 20 | G757: Yes | H757: Yes | I757: Fiber Optic | J757: No | K757: No | L757: Yes | M757: No | N757: Yes | O757: Yes | P757: Month-To-Month | Q757: Yes | R757: Electronic Check | S757: 98.55 | T757: =IF(Table1[[#This Row],[MonthlyCharges]]<=51,"Low",IF(Table1[[#This Row],[MonthlyCharges]]<=84,"Medium","High")) -> High | U757: 1842.8 | V757: Yes
A758: 5730-Dbdsi | B758: Male | C758: 0 | D758: No | E758: No | F758: 66 | G758: Yes | H758: No | I758: No | J758: No Internet Service | K758: No Internet Service | L758: No Internet Service | M758: No Internet Service | N758: No Internet Service | O758: No Internet Service | P758: Two Year | Q758: No | R758: Bank Transfer (Automatic) | S758: 19.7 | T758: =IF(Table1[[#This Row],[MonthlyCharges]]<=51,"Low",IF(Table1[[#This Row],[MonthlyCharges]]<=84,"Medium","High")) -> Low | U758: 1253.8 | V758: No
A759: 0030-Fnxpp | B759: Female | C759: 0 | D759: No | E759: No | F759: 3 | G759: Yes | H759: No | I759: No | J759: No Internet Service | K759: No Internet Service | L759: No Internet Service | M759: No Internet Service | N759: No Internet Service | O759: No Internet Service | P759: Month-To-Month | Q759: No | R759: Mailed Check | S759: 19.85 | T759: =IF(Table1[[#This Row],[MonthlyCharges]]<=51,"Low",IF(Table1[[#This Row],[MonthlyCharges]]<=84,"Medium","High")) -> Low | U759: 57.2 | V759: No
A760: 2189-Wwoew | B760: Female | C760: 0 | D760: No | E760: Yes | F760: 15 | G760: Yes | H760: No | I760: Fiber Optic | J760: No | K760: Yes | L760: No | M760: No | N760: No | O760: Yes | P760: Month-To-Month | Q760: Yes | R760: Bank Transfer (Automatic) | S760: 85.9 | T760: =IF(Table1[[#This Row],[MonthlyCharges]]<=51,"Low",IF(Table1[[#This Row],[MonthlyCharges]]<=84,"Medium","High")) -> High | U760: 1269.55 | V760: Yes
A761: 5684-Fjvyr | B761: Female | C761: 0 | D761: Yes | E761: Yes | F761: 72 | G761: Yes | H761: Yes | I761: Fiber Optic | J761: Yes | K761: Yes | L761: No | M761: Yes | N761: No | O761: No | P761: Two Year | Q761: Yes | R761: Bank Transfer (Automatic) | S761: 90.35 | T761: =IF(Table1[[#This Row],[MonthlyCharges]]<=51,"Low",IF(Table1[[#This Row],[MonthlyCharges]]<=84,"Medium","High")) -> High | U761: 6563.4 | V761: No
A762: 4013-Guxnd | B762: Male | C762: 0 | D762: No | E762: No | F762: 1 | G762: Yes | H762: No | I762: No | J762: No Internet Service | K762: No Internet Service | L762: No Internet Service | M762: No Internet Service | N762: No Internet Service | O762: No Internet Service | P762: Month-To-Month | Q762: No | R762: Mailed Check | S762: 20.8 | T762: =IF(Table1[[#This Row],[MonthlyCharges]]<=51,"Low",IF(Table1[[#This Row],[MonthlyCharges]]<=84,"Medium","High")) -> Low | U762: 20.8 | V762: No
A763: 1894-Igfsg | B763: Female | C763: 0 | D763: No | E763: No | F763: 22 | G763: Yes | H763: No | I763: Fiber Optic | J763: No | K763: No | L763: No | M763: No | N763: Yes | O763: Yes | P763: Month-To-Month | Q763: No | R763: Electronic Check | S763: 89.25 | T763: =IF(Table1[[#This Row],[MonthlyCharges]]<=51,"Low",IF(Table1[[#This Row],[MonthlyCharges]]<=84,"Medium","High")) -> High | U763: 1907.85 | V763: Yes
A764: 7379-Pokdz | B764: Male | C764: 0 | D764: Yes | E764: No | F764: 3 | G764: Yes | H764: No | I764: Fiber Optic | J764: No | K764: No | L764: No | M764: No | N764: No | O764: No | P764: Month-To-Month | Q764: Yes | R764: Electronic Check | S764: 70.3 | T764: =IF(Table1[[#This Row],[MonthlyCharges]]<=51,"Low",IF(Table1[[#This Row],[MonthlyCharges]]<=84,"Medium","High")) -> Medium | U764: 208.85 | V764: Yes
A765: 1266-Nzyui | B765: Female | C765: 0 | D765: Yes | E765: Yes | F765: 72 | G765: Yes | H765: Yes | I765: Dsl | J765: Yes | K765: No | L765: Yes | M765: Yes | N765: No | O765: No | P765: Two Year | Q765: No | R765: Bank Transfer (Automatic) | S765: 66.85 | T765: =IF(Table1[[#This Row],[MonthlyCharges]]<=51,"Low",IF(Table1[[#This Row],[MonthlyCharges]]<=84,"Medium","High")) -> Medium | U765: 4758.8 | V765: No
A766: 7969-Ffowg | B766: Male | C766: 0 | D766: Yes | E766: Yes | F766: 65 | G766: Yes | H766: No | I766: No | J766: No Internet Service | K766: No Internet Service | L766: No Internet Service | M766: No Internet Service | N766: No Internet Service | O766: No Internet Service | P766: Two Year | Q766: No | R766: Mailed Check | S766: 19.9 | T766: =IF(Table1[[#This Row],[MonthlyCharges]]<=51,"Low",IF(Table1[[#This Row],[MonthlyCharges]]<=84,"Medium","High")) -> Low | U766: 1292.6 | V766: No
...

Sheet Descriptive Stats
A1: SeniorCitizen | C1: tenure | E1: MonthlyCharges | G1: TotalCharges
A3: Mean | B3: 0.16214681 | C3: Mean | D3: 32.371149 | E3: Mean | F3: 64.761692 | G3: Mean | H3: 2283.3004
A4: Standard Error | B4: 0.0043922814 | C4: Standard Error | D4: 0.29264448 | E4: Standard Error | F4: 0.35854529 | G4: Standard Error | H4: 27.031384
A5: Median | B5: 0 | C5: Median | D5: 29 | E5: Median | F5: 70.35 | G5: Median | H5: 1397.475
A6: Mode | B6: 0 | C6: Mode | D6: 1 | E6: Mode | F6: 20.05 | G6: Mode | H6: 20.2
A7: Standard Deviation | B7: 0.36861161 | C7: Standard Deviation | D7: 24.559481 | E7: Standard Deviation | F7: 30.090047 | G7: Standard Deviation | H7: 2266.7714
A8: Sample Variance | B8: 0.13587452 | C8: Sample Variance | D8: 603.16811 | E8: Sample Variance | F8: 905.41093 | G8: Sample Variance | H8: 5138252.4
A9: Kurtosis | B9: 1.3625959 | C9: Kurtosis | D9: -1.3873716 | E9: Kurtosis | F9: -1.2572597 | G9: Kurtosis | H9: -0.23179876
A10: Skewness | B10: 1.8336327 | C10: Skewness | D10: 0.23953975 | E10: Skewness | F10: -0.22052443 | G10: Skewness | H10: 0.9616425
A11: Range | B11: 1 | C11: Range | D11: 72 | E11: Range | F11: 100.5 | G11: Range | H11: 8666
A12: Minimum | B12: 0 | C12: Minimum | D12: 0 | E12: Minimum | F12: 18.25 | G12: Minimum | H12: 18.8
A13: Maximum | B13: 1 | C13: Maximum | D13: 72 | E13: Maximum | F13: 118.75 | G13: Maximum | H13: 8684.8
A14: Sum | B14: 1142 | C14: Sum | D14: 227990 | E14: Sum | F14: 456116.6 | G14: Sum | H14: 16056169
A15: Count | B15: 7043 | C15: Count | D15: 7043 | E15: Count | F15: 7043 | G15: Count | H15: 7032

Sheet ANALYSIS
A1: Row Labels | B1: Count of customerID | F1: Row Labels | G1: Count of customerID | K1: Count of customerID | L1: Column Labels
A2: 0 | B2: 5901 | F2: Female | G2: 3488 | K2: Row Labels | L2: No | M2: Yes | N2: Grand Total | P2: Count of customerID | Q2: Column Labels | U2: Count of customerID | V2: Column Labels | Z2: Count of customerID | AA2: Column Labels | AE2: Count of customerID | AF2: Column Labels | AJ2: Count of customerID | AK2: Column Labels | AO2: Count of customerID | AP2: Column Labels | AT2: Count of customerID | AU2: Column Labels | AY2: Count of customerID | AZ2: Column Labels | BF2: Count of customerID | BG2: Column Labels | BL2: Count of customerID | BM2: Column Labels | BR2: Count of customerID | BS2: Column Labels | BW2: Count of customerID | BX2: Column Labels | CB2: Count of customerID | CC2: Column Labels | CG2: Count of customerID | CH2: Column Labels | CL2: Count of customerID | CM2: Column Labels | CQ2: Count of customerID | CR2: Column Labels | CV2: Count of customerID | CW2: Column Labels
A3: 1 | B3: 1142 | F3: Male | G3: 3555 | K3: Dsl | L3: 0.81040892 | M3: 0.18959108 | N3: 1 | P3: Row Labels | Q3: No | R3: Yes | S3: Grand Total | U3: Row Labels | V3: No | W3: Yes | X3: Grand Total | Y3: =GETPIVOTDATA("customerID",$U$2,"tenure",0,"Churn","Yes")/GETPIVOTDATA("customerID",$U$2,"tenure",0)*100 -> 48.284195 | Z3: Row Labels | AA3: No | AB3: Yes | AC3: Grand Total | AD3: =GETPIVOTDATA("customerID",$Z$2,"PaperlessBilling","No","Churn","Yes")/GETPIVOTDATA("customerID",$Z$2,"PaperlessBilling","No")*100 -> 16.330084 | AE3: Row Labels | AF3: No | AG3: Yes | AH3: Grand Total | AJ3: Row Labels | AK3: No | AL3: Yes | AM3: Grand Total | AO3: Row Labels | AP3: No | AQ3: Yes | AR3: Grand Total | AT3: Row Labels | AU3: No | AV3: Yes | AW3: Grand Total | AY3: Row Labels | AZ3: Bank Transfer (Automatic) | BA3: Credit Card (Automatic) | BB3: Electronic Check | BC3: Mailed Check | BD3: Grand Total | BF3: Row Labels | BG3: Month-To-Month | BH3: One Year | BI3: Two Year | BJ3: Grand Total | BL3: Row Labels | BM3: Month-To-Month | BN3: One Year | BO3: Two Year | BP3: Grand Total | BR3: Row Labels | BS3: No | BT3: Yes | BU3: Grand Total | BW3: Row Labels | BX3: No | BY3: Yes | BZ3: Grand Total | CB3: Row Labels | CC3: No | CD3: Yes | CE3: Grand Total | CG3: Row Labels | CH3: No | CI3: Yes | CJ3: Grand Total | CL3: Row Labels | CM3: No | CN3: Yes | CO3: Grand Total | CQ3: Row Labels | CR3: No | CS3: Yes | CT3: Grand Total | CV3: Row Labels | CW3: No | CX3: Yes | CY3: Grand Total
A4: Grand Total | B4: 7043 | F4: Grand Total | G4: 7043 | K4: Fiber Optic | L4: 0.58107235 | M4: 0.41892765 | N4: 1 | P4: No | Q4: 0.74955752 | R4: 0.25044248 | S4: 1 | U4: 0-11 | V4: 0.51715805 | W4: 0.48284195 | X4: 1 | Z4: No | AA4: 0.83669916 | AB4: 0.16330084 | AC4: 1 | AE4: Bank Transfer (Automatic) | AF4: 0.83290155 | AG4: 0.16709845 | AH4: 1 | AJ4: No | AK4: 0.67042021 | AL4: 0.32957979 | AM4: 1 | AO4: High | AP4: 0.65926558 | AQ4: 0.34073442 | AR4: 1 | AT4: No | AU4: 0.6872086 | AV4: 0.3127914 | AW4: 1 | AY4: Month-To-Month | AZ4: 589 | BA4: 543 | BB4: 1850 | BC4: 893 | BD4: 3875 | BF4: Dsl | BG4: 1223 | BH4: 570 | BI4: 628 | BJ4: 2421 | BL4: No | BM4: 1289 | BN4: 673 | BO4: 910 | BP4: 2872 | BR4: Bank Transfer (Automatic) | BS4: 653 | BT4: 891 | BU4: 1544 | BW4: No | BX4: 0.75073314 | BY4: 0.24926686 | BZ4: 1 | CB4: No | CC4: 0.66476868 | CD4: 0.33523132 | CE4: 1 | CG4: No | CH4: 0.66319569 | CI4: 0.33680431 | CJ4: 1 | CL4: Female | CM4: 0.73079128 | CN4: 0.26920872 | CO4: 1 | CQ4: 0 | CR4: 0.76393832 | CS4: 0.23606168 | CT4: 1 | CV4: No | CW4: 0.75073314 | CX4: 0.24926686 | CY4: 1
D5: =GETPIVOTDATA("customerID",$A$8,"Churn","No")/GETPIVOTDATA("customerID",$A$8)*100 -> 73.463013 | K5: No | L5: 0.9259502 | M5: 0.074049803 | N5: 1 | P5: No Phone Service | Q5: 0.75073314 | R5: 0.24926686 | S5: 1 | U5: 12-23 | V5: 0.70487106 | W5: 0.29512894 | X5: 1 | Z5: Yes | AA5: 0.66434908 | AB5: 0.33565092 | AC5: 1 | AD5: =GETPIVOTDATA("customerID",$Z$2,"PaperlessBilling","Yes","Churn","Yes")/GETPIVOTDATA("customerID",$Z$2,"PaperlessBilling","Yes")*100 -> 33.565092 | AE5: Credit Card (Automatic) | AF5: 0.84756899 | AG5: 0.15243101 | AH5: 1 | AJ5: Yes | AK5: 0.80335097 | AL5: 0.19664903 | AM5: 1 | AO5: Low | AP5: 0.83574679 | AQ5: 0.16425321 | AR5: 1 | AT5: Yes | AU5: 0.84549763 | AV5: 0.15450237 | AW5: 1 | AY5: One Year | AZ5: 391 | BA5: 398 | BB5: 347 | BC5: 337 | BD5: 1473 | BF5: Fiber Optic | BG5: 2128 | BH5: 539 | BI5: 429 | BJ5: 3096 | BL5: Yes | BM5: 2586 | BN5: 800 | BO5: 785 | BP5: 4171 | BR5: Credit Card (Automatic) | BS5: 640 | BT5: 882 | BU5: 1522 | BW5: Yes | BX5: 0.73290363 | BY5: 0.26709637 | BZ5: 1 | CB5: No Internet Service | CC5: 0.9259502 | CD5: 0.074049803 | CE5: 1 | CG5: No Internet Service | CH5: 0.9259502 | CI5: 0.074049803 | CJ5: 1 | CL5: Male | CM5: 0.73839662 | CN5: 0.26160338 | CO5: 1 | CQ5: 1 | CR5: 0.58318739 | CS5: 0.41681261 | CT5: 1 | CV5: Yes | CW5: 0.73290363 | CX5: 0.26709637 | CY5: 1
K6: Grand Total | L6: 0.73463013 | M6: 0.26536987 | N6: 1 | P6: Yes | Q6: 0.71390104 | R6: 0.28609896 | S6: 1 | U6: 24-35 | V6: 0.77968037 | W6: 0.22031963 | X6: 1 | Z6: Grand Total | AA6: 0.73463013 | AB6: 0.26536987 | AC6: 1 | AE6: Electronic Check | AF6: 0.54714588 | AG6: 0.45285412 | AH6: 1 | AJ6: Grand Total | AK6: 0.73463013 | AL6: 0.26536987 | AM6: 1 | AO6: Medium | AP6: 0.70490368 | AQ6: 0.29509632 | AR6: 1 | AT6: Grand Total | AU6: 0.73463013 | AV6: 0.26536987 | AW6: 1 | AY6: Two Year | AZ6: 564 | BA6: 581 | BB6: 168 | BC6: 382 | BD6: 1695 | BF6: No | BG6: 524 | BH6: 364 | BI6: 638 | BJ6: 1526 | BL6: Grand Total | BM6: 3875 | BN6: 1473 | BO6: 1695 | BP6: 7043 | BR6: Electronic Check | BS6: 623 | BT6: 1742 | BU6: 2365 | BW6: Grand Total | BX6: 0.73463013 | BY6: 0.26536987 | BZ6: 1 | CB6: Yes | CC6: 0.69929812 | CD6: 0.30070188 | CE6: 1 | CG6: Yes | CH6: 0.70058565 | CI6: 0.29941435 | CJ6: 1 | CL6: Grand Total | CM6: 0.73463013 | CN6: 0.26536987 | CO6: 1 | CQ6: Grand Total | CR6: 0.73463013 | CS6: 0.26536987 | CT6: 1 | CV6: Grand Total | CW6: 0.73463013 | CX6: 0.26536987 | CY6: 1
D7: CHURN RATE | F7: Count of customerID | G7: Column Labels | P7: Grand Total | Q7: 0.73463013 | R7: 0.26536987 | S7: 1 | U7: 36-47 | V7: 0.80481283 | W7: 0.19518717 | X7: 1 | AE7: Mailed Check | AF7: 0.808933 | AG7: 0.191067 | AH7: 1 | AO7: Grand Total | AP7: 0.73463013 | AQ7: 0.26536987 | AR7: 1 | AY7: Grand Total | AZ7: 1544 | BA7: 1522 | BB7: 2365 | BC7: 1612 | BD7: 7043 | BF7: Grand Total | BG7: 3875 | BH7: 1473 | BI7: 1695 | BJ7: 7043 | BR7: Mailed Check | BS7: 956 | BT7: 656 | BU7: 1612 | CB7: Grand Total | CC7: 0.73463013 | CD7: 0.26536987 | CE7: 1 | CG7: Grand Total | CH7: 0.73463013 | CI7: 0.26536987 | CJ7: 1
A8: Row Labels | B8: Count of customerID | D8: =GETPIVOTDATA("customerID",$A$8,"Churn","Yes")/GETPIVOTDATA("customerID",$A$8) -> 0.26536987 | F8: Row Labels | G8: No | H8: Yes | I8: Grand Total | U8: 48-59 | V8: 0.85 | W8: 0.15 | X8: 1 | AE8: Grand Total | AF8: 0.73463013 | AG8: 0.26536987 | AH8: 1 | BR8: Grand Total | BS8: 2872 | BT8: 4171 | BU8: 7043
A9: No | B9: 5174 | F9: Month-To-Month | G9: 0.57290323 | H9: 0.42709677 | I9: 1 | U9: 60-72 | V9: 0.93324343 | W9: 0.066756575 | X9: 1 | Y9: =GETPIVOTDATA("customerID",$U$2,"tenure",60,"Churn","Yes")/GETPIVOTDATA("customerID",$U$2,"tenure",60)*100 -> 6.6756575
A10: Yes | B10: 1869 | D10: =GETPIVOTDATA("customerID",$A$8,"Churn","Yes")/GETPIVOTDATA("customerID",$A$8)*100 -> 26.536987 | F10: One Year | G10: 0.88730482 | H10: 0.11269518 | I10: 1 | U10: Grand Total | V10: 0.73463013 | W10: 0.26536987 | X10: 1 | CW10: =GETPIVOTDATA("tenure",$CV$11) -> 72
A11: Grand Total | B11: 7043 | D11: =GETPIVOTDATA("customerID",$A$8) -> 7043 | F11: Two Year | G11: 0.97168142 | H11: 0.028318584 | I11: 1 | CV11: Max of tenure
F12: Grand Total | G12: 0.73463013 | H12: 0.26536987 | I12: 1 | CV12: 72
K13: =D8 -> 0.26536987
A14: Count of customerID | B14: Column Labels
A15: Row Labels | B15: No | C15: Yes | D15: Grand Total | CW15: Average of MonthlyCharges
A16: 0 | B16: 4508 | C16: 1393 | D16: 5901 | CW16: 64.761692
A17: Month-To-Month | B17: 1854 | C17: 1214 | D17: 3068
A18: One Year | B18: 1146 | C18: 137 | D18: 1283
A19: Two Year | B19: 1508 | C19: 42 | D19: 1550
A20: 1 | B20: 666 | C20: 476 | D20: 1142
A21: Month-To-Month | B21: 366 | C21: 441 | D21: 807
A22: One Year | B22: 161 | C22: 29 | D22: 190
A23: Two Year | B23: 139 | C23: 6 | D23: 145 | CY23: =CV12 -> 72
A24: Grand Total | B24: 5174 | C24: 1869 | D24: 7043

Sheet DASHBOARD
BH23: z

Sheet Sheet1
B1: SeniorCitizen | C1: tenure | D1: MonthlyCharges | E1: TotalCharges
A2: SeniorCitizen | B2: 1
A3: tenure | B3: 0.016566878 | C3: 1
A4: MonthlyCharges | B4: 0.22017334 | C4: 0.24789986 | D4: 1
A5: TotalCharges | B5: 0.10241061 | C5: 0.82588046 | D5: 0.6510648 | E5: 1

Sheet Numeric Extract
A1: SeniorCitizen | B1: tenure | C1: MonthlyCharges | D1: TotalCharges
A2: 0 | B2: 1 | C2: 29.85 | D2: 29.85
A3: 0 | B3: 34 | C3: 56.95 | D3: 1889.5
A4: 0 | B4: 2 | C4: 53.85 | D4: 108.15
A5: 0 | B5: 45 | C5: 42.3 | D5: 1840.75
A6: 0 | B6: 2 | C6: 70.7 | D6: 151.65
A7: 0 | B7: 8 | C7: 99.65 | D7: 820.5
A8: 0 | B8: 22 | C8: 89.1 | D8: 1949.4
A9: 0 | B9: 10 | C9: 29.75 | D9: 301.9
A10: 0 | B10: 28 | C10: 104.8 | D10: 3046.05
A11: 0 | B11: 62 | C11: 56.15 | D11: 3487.95
A12: 0 | B12: 13 | C12: 49.95 | D12: 587.45
A13: 0 | B13: 16 | C13: 18.95 | D13: 326.8
... A489: 0 | B489: 72 | C489: 88.6 | D489: 6201.95
A490: 0 | B490: 0 | C490: 52.55
A491: 0 | B491: 1 | C491: 74.35 | D491: 74.35
A492: 0 | B492: 63 | C492: 104.8 | D492: 6597.25
A493: 0 | B493: 2 | C493: 59 | D493: 114.15
A494: 0 | B494: 2 | C494: 74.4 | D494: 139.4
A495: 1 | B495: 61 | C495: 64.05 | D495: 3902.6
A496: 0 | B496: 1 | C496: 20.4 | D496: 20.4
A497: 0 | B497: 22 | C497: 43.75 | D497: 903.6
A498: 0 | B498: 28 | C498: 60.9 | D498: 1785.65
A499: 0 | B499: 70 | C499: 19.8 | D499: 1397.65
A500: 1 | B500: 5 | C500: 28.45 | D500: 131.05
A501: 0 | B501: 12 | C501: 99.7 | D501: 1238.45
A502: 0 | B502: 34 | C502: 116.25 | D502: 3899.05
... A754: 0 | B754: 7 | C754: 71.35 | D754: 515.75
A755: 0 | B755: 0 | C755: 20.25
A756: 0 | B756: 2 | C756: 90.35 | D756: 190.5
A757: 1 | B757: 20 | C757: 98.55 | D757: 1842.8
A758: 0 | B758: 66 | C758: 19.7 | D758: 1253.8
A759: 0 | B759: 3 | C759: 19.85 | D759: 57.2
A760: 0 | B760: 15 | C760: 85.9 | D760: 1269.55
A761: 0 | B761: 72 | C761: 90.35 | D761: 6563.4
A762: 0 | B762: 1 | C762: 20.8 | D762: 20.8
A763: 0 | B763: 22 | C763: 89.25 | D763: 1907.85
A764: 0 | B764: 3 | C764: 70.3 | D764: 208.85
A765: 0 | B765: 72 | C765: 66.85 | D765: 4758.8
A766: 0 | B766: 65 | C766: 19.9 | D766: 1292.6
...
